<?xml version="1.0"?>
<robot xmlns:xacro="http://www.ros.org/wiki/xacro" name="carmodel">


<xacro:property name="bodyLength" value="0.4" />
<xacro:property name="bodyWidth" value="0.6" />
<xacro:property name="bodyHeight" value="0.2" />
<xacro:property name="bodyMass" value="100.0" />

<xacro:property name="wheelLength" value="0.1" />
<xacro:property name="wheelRadius" value="0.15" />
<xacro:property name="wheelMass" value="${ bodyMass * (0.15*0.15*3.14*0.1)/(0.4*0.6*0.2) }" />


<xacro:property name="inertLength" value="${ bodyMass/12 * ( (bodyWidth*bodyWidth)   + (bodyHeight*bodyHeight) ) }" />
<xacro:property name="inertWidth"  value="${ bodyMass/12 * ( (bodyLength*bodyLength) + (bodyHeight*bodyHeight) ) }" />
<xacro:property name="inertHeight" value="${ bodyMass/12 * ( (bodyLength*bodyLength) + (bodyWidth*bodyWidth)   ) }" />


<xacro:property name="inertX"  value="${ wheelMass * (wheelRadius*wheelRadius) / 2 }" />
<xacro:property name="inertYZ" value="${ (wheelMass/12) * ( 3*(wheelRadius*wheelRadius) + (wheelLength*wheelLength) ) }" />



  <material name="blue">
    <color rgba="0 0 .8 1"/>
  </material>

  <material name="black">
    <color rgba="0 0 0 1"/>
  </material>

  <material name="white">
    <color rgba="1 1 1 1"/>
  </material>


  <link name="base_link">
    <visual>
      <geometry>
        <box size = "0.4 0.6 0.2"/>
      </geometry>
      <material name="blue"/>
    </visual>
    <collision>
        <geometry>
                <box size = "0.8 1.2 0.4"/>
        </geometry>
    </collision>

  </link>




  <link name="front_left_wheel">
    <visual>
      <geometry>
        <cylinder length="0.1" radius="0.15"/>
      </geometry>
      <origin rpy="0 1.57075 0"/>
      <material name="white"/>
    </visual>


  </link>

  <joint name="base_to_front_left_wheel" type="continuous">
    <parent link="base_link"/>
    <child link="front_left_wheel"/>
    <origin xyz="-0.25 0.3 -0.1"/>
  </joint>



  <link name="front_right_wheel">
    <visual>
      <geometry>
        <cylinder length="0.1" radius="0.15"/>
      </geometry>
      <origin rpy="0 1.57075 -0.1"/>
      <material name="white"/>
    </visual>


  </link>

  <joint name="base_to_front_right_wheel" type="continuous">
    <parent link="base_link"/>
    <child link="front_right_wheel"/>
    <origin xyz="0.25 0.3 -0.1"/>
  </joint>




  <link name="back_left_wheel">
    <visual>
      <geometry>
        <cylinder length="0.1" radius="0.15"/>
      </geometry>
      <origin rpy="1.57075 1.57075 1.57075"/>
      <material name="white"/>
    </visual>


  </link>

  <joint name="base_to_back_left_wheel" type="fixed">
    <parent link="base_link"/>
    <child link="back_left_wheel"/>
    <origin xyz="-0.25 -0.3 -0.1"/>
  </joint>



  <link name="back_right_wheel">
    <visual>
      <geometry>
        <cylinder length="0.1" radius="0.15"/>
      </geometry>
      <origin rpy="0 1.57075 0"/>
      <material name="white"/>
    </visual>


  </link>

  <joint name="base_to_back_right_wheel" type="fixed">
    <parent link="base_link"/>
    <child link="back_right_wheel"/>
    <origin xyz="0.25 -0.3 -0.1"/>
  </joint>



</robot>
